Workbook
Name FY: Settings!$B$5
Name IncPct: Settings!$B$6
Name IncMonth: Settings!$B$7
Name BonusMonths: Settings!$B$8
Name SI_O: Settings!$B$9
Name SI_E: Settings!$B$10
Name SI_Base: Settings!$B$11
Name EOSB: Settings!$B$12
Name Ticket: Settings!$B$13
Name MedO: Settings!$B$14
Name MedE: Settings!$B$15
Name Training: Settings!$B$16
Name RecO: Settings!$B$17
Name RecE: Settings!$B$18
Name Contingency: Settings!$B$19
Name OmanTarget: Settings!$B$20
Name RetAgeO: Settings!$B$21
Name RetAgeE: Settings!$B$22
Name RetireExit: Settings!$B$23
Name ContractExit: Settings!$B$24
Name SI_Gross: Settings!$B$26
Name Unconfirmed: Settings!$B$27

Sheet Guide
A1: Manpower Budget Workbook
A2: Every figure is calculated from the employee data you paste into the Data sheet. This template contains no data.
A4: How to use it
A5: 1 | B5: Settings: set the budget year and check every assumption. Mark each one Confirmed once Payroll or Finance has agreed it.
A6: 2 | B6: Departments: type each department exactly as it is written in your HR export, with its overtime %, last year's budget and ceiling.
A7: 3 | B7: Data: paste your employee export as values into columns A to P, starting at row 2 (Home > Paste > Paste Values). Do not type in the grey columns: they calculate themselves.
A8: 4 | B8: Data, column AL (Check): fix every row it flags. Overview shows how many rows still have issues.
A9: 5 | B9: Plan: add planned new hires and other exits that are not in the employee data.
A10: 6 | B10: Overview: the budget, budget bridge, reconciliation checks and charts update automatically. Budget by Dept and Monthly give the detail.
A12: Colour legend
A13: Blue text | B13: Something you type or paste (inputs).
A14: Yellow cell | B14: A key assumption that must be confirmed before the budget is submitted.
A15: Grey column | B15: Calculated. Do not type here.
A16: Green text | B16: Pulled from another sheet.
A18: Rules the workbook follows
A19: Data first | B19: Nothing is filled in for you. Headcount, pay, departments and leavers all come from the Data sheet.
A20: Traceable | B20: Every department figure is a SUMIFS or COUNTIFS over the Data sheet. Filter the Data sheet by department to see the rows behind any number.
A21: Reconciled | B21: Overview compares the totals by department with the raw Data totals. Any difference (for example a department missing from the Departments sheet) is shown in red.
A22: Capacity | B22: Up to 5,000 employees, 50 departments and 300 plan lines.
A24: Data sheet format: one example row (do not paste this into the Data sheet)
A25: Employee ID | B25: Employee name | C25: Department * | D25: Section | E25: Job title | F25: Grade | G25: Nationality * | H25: Gender | I25: Date of birth | J25: Joining date | K25: Contract end date | L25: Basic salary (OMR / month) * | M25: Allowances total (OMR / month) | N25: Employment status | O25: Planned exit month (1-12, optional) | P25: Personal increment % (optional)
A26: E10234 | B26: Example Employee | C26: Engineering & Maintenance | D26: Line Maintenance | E26: Licensed Engineer B1 | F26: T3 | G26: Omani | H26: Male | I26: 14/03/1985 | J26: 01/09/2012 | L26: 1350 | M26: 650 | N26: Active
A27: Dates must be real Excel dates (not text). Nationality: Omani, Oman, OM or Local counts as Omani; anything else is expatriate. Status containing resign, terminat, inactive, vacan, deceased or separated is treated as not active.

Sheet Overview
A1: Overview
A2: Calculated from the Data, Plan, Departments and Settings sheets. Nothing on this sheet is typed in.
A4: Data source
A5: Rows in the Data sheet | B5: =COUNTA(Data!$C$2:$C$5001) | C5: =IF(B5=0,"No data yet: paste your employee export into the Data sheet. All figures below stay at zero until then.","")
A6: Active employees | B6: =SUM(Data!$R$2:$R$5001)
A7: Rows with data issues (fix on Data, column AL) | B7: =COUNTIF(Data!$AL$2:$AL$5001,"Basic*")+COUNTIF(Data!$AL$2:$AL$5001,"Department*")+COUNTIF(Data!$AL$2:$AL$5001,"Date*")+COUNTIF(Data!$AL$2:$AL$5001,"Contract*")
A8: Assumptions not yet confirmed (Settings) | B8: =Unconfirmed
A10: Key figures
A11: FY budget (OMR) | B11: =Departments!S55
A12: Prior-year budget (OMR) | B12: =Departments!C55
A13: Change vs prior year | B13: =IF(B12=0,"",B11/B12-1)
A14: Headcount today | B14: =Departments!E55
A15: Closing headcount | B15: =Departments!O55
A16: Omanisation today | B16: =IF(B6=0,"",SUMPRODUCT(Data!$Q$2:$Q$5001,Data!$R$2:$R$5001)/B6)
A17: Omanisation at year end | B17: =Departments!V55 | C17: =IF(OR(B17="",B18=""),"",IF(B17>=B18,"Meets target","Below target"))
A18: Omanisation target | B18: =OmanTarget
A19: Average FTE in the year | B19: =SUM(Data!$W$2:$W$5001)/12+SUMPRODUCT(Plan!$T$5:$T$304,Plan!$P$5:$P$304)/12
A20: Average cost per FTE (OMR) | B20: =IF(N(B19)=0,"",B11/B19)
A22: Budget bridge
A23: Step | B23: OMR | C23: Explanation | E23: Base | F23: Increase | G23: Decrease
A24: Payroll run-rate today | B24: =SUM(Data!$AI$2:$AI$5001) | C24: Active staff at today's pay for 12 months, with all on-costs, no increment. | E24: 0 | F24: =B24 | G24: 0
A25: Salary increment | B25: =SUM(Data!$AJ$2:$AJ$5001)-SUM(Data!$AI$2:$AI$5001) | C25: Increment from its effective month (personal rates where given). | E25: =MIN(SUM($B$24:B24),SUM($B$24:B24)+B25) | F25: =MAX(B25,0) | G25: =MAX(-B25,0)
A26: Named leavers | B26: =SUM(Data!$AH$2:$AH$5001)-SUM(Data!$AJ$2:$AJ$5001) | C26: Planned exits, and retirements or contract ends when Settings says to treat them as exits. | E26: =MIN(SUM($B$24:B25),SUM($B$24:B25)+B26) | F26: =MAX(B26,0) | G26: =MAX(-B26,0)
A27: Planned hires | B27: =SUMIFS(Plan!$S$5:$S$304,Plan!$A$5:$A$304,"Hire") | C27: New positions on the Plan sheet, including recruitment. | E27: =MIN(SUM($B$24:B26),SUM($B$24:B26)+B27) | F27: =MAX(B27,0) | G27: =MAX(-B27,0)
A28: Other exits (attrition) | B28: =SUMIFS(Plan!$S$5:$S$304,Plan!$A$5:$A$304,"Exit") | C28: Exits on the Plan sheet. | E28: =MIN(SUM($B$24:B27),SUM($B$24:B27)+B28) | F28: =MAX(B28,0) | G28: =MAX(-B28,0)
A29: Contingency | B29: =Departments!R55 | C29: Contingency % on each department's total. | E29: =MIN(SUM($B$24:B28),SUM($B$24:B28)+B29) | F29: =MAX(B29,0) | G29: =MAX(-B29,0)
A30: FY budget | B30: =SUM(B24:B29) | C30: Sum of the steps above. | E30: 0 | F30: =B30 | G30: 0
A31: Check: bridge equals budget | B31: =IF(ROUND(B30-B11,0)=0,"OK","Differs by "&TEXT(B30-B11,"#,##0")&": a department in Data is missing from Departments")
A33: Reconciliation with the Data sheet
A34: Measure | B34: Data sheet total | C34: By department | D34: Difference | E34: Status
A35: Active headcount | B35: =SUM(Data!$R$2:$R$5001) | C35: =Departments!E55 | D35: =B35-C35 | E35: =IF(ROUND(D35,0)=0,"✓ Matches","✗ Check")
A36: Monthly gross pay today (OMR) | B36: =SUM(Data!$AK$2:$AK$5001) | C36: =Departments!I55 | D36: =B36-C36 | E36: =IF(ROUND(D36,0)=0,"✓ Matches","✗ Check")
A37: Staff FY cost (OMR) | B37: =SUM(Data!$AH$2:$AH$5001) | C37: =Departments!P55 | D37: =B37-C37 | E37: =IF(ROUND(D37,0)=0,"✓ Matches","✗ Check")
A38: FY budget vs monthly phasing (OMR) | B38: =Monthly!N9 | C38: =Departments!S55 | D38: =B38-C38 | E38: =IF(ROUND(D38,0)=0,"✓ Matches","✗ Check")

Sheet Settings
A1: Settings and assumptions
A2: Assumptions are not data. Each one is shown here, used by name in the formulas, and must be confirmed.
A4: Assumption | B4: Value | C4: Unit | D4: Confirmed? | E4: Source / note
A5: Budget year | B5: 2027 | C5: year | D5: No | E5: Fiscal year being budgeted.
A6: Annual increment | B6: 0.03 | C6: % of basic and allowances | D6: No | E6: Default 3%. Confirm with Compensation.
A7: Increment effective month | B7: 1 | C7: month 1-12 | D7: No | E7: 1 = January.
A8: Bonus / incentive | B8: 1 | C8: months of basic | D8: No | E8: Accrued evenly.
A9: Employer social protection, Omani | B9: 0.125 | C9: % of contribution base | D9: No | E9: Default 12.5%. Confirm the current Social Protection Fund schedule with Payroll.
A10: Employer contribution, expatriate | B10: 0.01 | C10: % of contribution base | D10: No | E10: Default 1% (occupational injury). Confirm with Payroll.
A11: Contribution base | B11: Basic + allowances | C11: list | D11: No | E11: Basic + allowances, or Basic only.
A12: Expatriate end-of-service accrual | B12: 0.0833 | C12: % of basic | D12: No | E12: 8.33% = one month's basic per year. Confirm against the Labour Law and contracts.
A13: Expatriate annual air ticket | B13: 350 | C13: OMR per head per year | D13: No | E13: Confirm with Travel / HR policy.
A14: Medical insurance, Omani | B14: 280 | C14: OMR per head per year | D14: No | E14: Confirm with the insurer's current premium.
A15: Medical insurance, expatriate | B15: 420 | C15: OMR per head per year | D15: No | E15: Confirm with the insurer's current premium.
A16: Training | B16: 220 | C16: OMR per head per year | D16: No | E16: Excludes type ratings and licences budgeted elsewhere.
A17: Recruitment cost, Omani hire | B17: 400 | C17: OMR per hire | D17: No | E17: Advertising, assessment, medicals.
A18: Recruitment cost, expatriate hire | B18: 1800 | C18: OMR per hire | D18: No | E18: Agency, visa, medical, relocation.
A19: Contingency | B19: 0.02 | C19: % of department total | D19: No
A20: Omanisation target | B20: 0.85 | C20: % of closing headcount | D20: No | E20: Company target.
A21: Retirement age, Omani | B21: 60 | C21: years | D21: No | E21: Used to find retirements in the budget year.
A22: Retirement age, expatriate | B22: 60 | C22: years | D22: No
A23: Treat retirements as exits | B23: No | C23: Yes / No | D23: No | E23: Yes = people reaching retirement age are paid only until their birth month.
A24: Treat contract ends as exits | B24: No | C24: Yes / No | D24: No | E24: Yes = people whose contract ends in the year are paid only until that month.
A26: Contribution base includes allowances (1 = yes) | B26: =IF(SI_Base="Basic only",0,1)
A27: Assumptions not yet confirmed | B27: =COUNTIF(D5:D24,"<>Yes")

Sheet Departments
A1: Departments
A2: Type the departments exactly as they appear in the Data sheet. Everything from column E onwards is calculated from the data.
A3: Departments found in Data but missing here: | E3: =COUNTIF(Data!$AL$2:$AL$5001,"Department not on Departments sheet")
A4: Department | B4: Overtime % of basic | C4: Prior-year budget (OMR) | D4: FY ceiling (OMR) | E4: Headcount today | F4: Omani today | G4: Omani % today | H4: Women | I4: Monthly gross today (OMR) | J4: Named leavers in FY | K4: Reaching retirement age | L4: Contracts ending | M4: Planned hires | N4: Planned other exits | O4: Closing headcount | P4: Staff FY cost (OMR) | Q4: Plan lines cost (OMR) | R4: Contingency (OMR) | S4: FY budget (OMR) | T4: Change vs prior year (OMR) | U4: Ceiling status | V4: Closing Omani %
E5: =IF($A5="","",COUNTIFS(Data!$C$2:$C$5001,$A5,Data!$R$2:$R$5001,1)) | F5: =IF($A5="","",COUNTIFS(Data!$C$2:$C$5001,$A5,Data!$R$2:$R$5001,1,Data!$Q$2:$Q$5001,1)) | G5: =IF(OR($A5="",N(E5)=0),"",F5/E5) | H5: =IF($A5="","",COUNTIFS(Data!$C$2:$C$5001,$A5,Data!$R$2:$R$5001,1,Data!$H$2:$H$5001,"F*")) | I5: =IF($A5="","",SUMIFS(Data!$AK$2:$AK$5001,Data!$C$2:$C$5001,$A5)) | J5: =IF($A5="","",COUNTIFS(Data!$C$2:$C$5001,$A5,Data!$R$2:$R$5001,1,Data!$W$2:$W$5001,"<12")) | K5: =IF($A5="","",COUNTIFS(Data!$C$2:$C$5001,$A5,Data!$U$2:$U$5001,">0")) | L5: =IF($A5="","",COUNTIFS(Data!$C$2:$C$5001,$A5,Data!$V$2:$V$5001,">0")) | M5: =IF($A5="","",SUMIFS(Plan!$E$5:$E$304,Plan!$B$5:$B$304,$A5,Plan!$A$5:$A$304,"Hire")) | N5: =IF($A5="","",SUMIFS(Plan!$E$5:$E$304,Plan!$B$5:$B$304,$A5,Plan!$A$5:$A$304,"Exit")) | O5: =IF($A5="","",E5-J5+M5-N5) | P5: =IF($A5="","",SUMIFS(Data!$AH$2:$AH$5001,Data!$C$2:$C$5001,$A5)) | Q5: =IF($A5="","",SUMIFS(Plan!$S$5:$S$304,Plan!$B$5:$B$304,$A5)) | R5: =IF($A5="","",(P5+Q5)*Contingency) | S5: =IF($A5="","",P5+Q5+R5) | T5: =IF(OR($A5="",N(C5)=0),"",S5-C5) | U5: =IF(OR($A5="",N(D5)=0),"",IF(S5>D5,"Over by "&TEXT(S5-D5,"#,##0"),"Within ceiling")) | V5: =IF(OR($A5="",N(O5)=0),"",(F5-COUNTIFS(Data!$C$2:$C$5001,$A5,Data!$R$2:$R$5001,1,Data!$Q$2:$Q$5001,1,Data!$W$2:$W$5001,"<12")+SUMIFS(Plan!$E$5:$E$304,Plan!$B$5:$B$304,$A5,Plan!$A$5:$A$304,"Hire",Plan!$D$5:$D$304,"Omani")-SUMIFS(Plan!$E$5:$E$304,Plan!$B$5:$B$304,$A5,Plan!$A$5:$A$304,"Exit",Plan!$D$5:$D$304,"Omani"))/O5)
E6: =IF($A6="","",COUNTIFS(Data!$C$2:$C$5001,$A6,Data!$R$2:$R$5001,1)) | F6: =IF($A6="","",COUNTIFS(Data!$C$2:$C$5001,$A6,Data!$R$2:$R$5001,1,Data!$Q$2:$Q$5001,1)) | G6: =IF(OR($A6="",N(E6)=0),"",F6/E6) | H6: =IF($A6="","",COUNTIFS(Data!$C$2:$C$5001,$A6,Data!$R$2:$R$5001,1,Data!$H$2:$H$5001,"F*")) | I6: =IF($A6="","",SUMIFS(Data!$AK$2:$AK$5001,Data!$C$2:$C$5001,$A6)) | J6: =IF($A6="","",COUNTIFS(Data!$C$2:$C$5001,$A6,Data!$R$2:$R$5001,1,Data!$W$2:$W$5001,"<12")) | K6: =IF($A6="","",COUNTIFS(Data!$C$2:$C$5001,$A6,Data!$U$2:$U$5001,">0")) | L6: =IF($A6="","",COUNTIFS(Data!$C$2:$C$5001,$A6,Data!$V$2:$V$5001,">0")) | M6: =IF($A6="","",SUMIFS(Plan!$E$5:$E$304,Plan!$B$5:$B$304,$A6,Plan!$A$5:$A$304,"Hire")) | N6: =IF($A6="","",SUMIFS(Plan!$E$5:$E$304,Plan!$B$5:$B$304,$A6,Plan!$A$5:$A$304,"Exit")) | O6: =IF($A6="","",E6-J6+M6-N6) | P6: =IF($A6="","",SUMIFS(Data!$AH$2:$AH$5001,Data!$C$2:$C$5001,$A6)) | Q6: =IF($A6="","",SUMIFS(Plan!$S$5:$S$304,Plan!$B$5:$B$304,$A6)) | R6: =IF($A6="","",(P6+Q6)*Contingency) | S6: =IF($A6="","",P6+Q6+R6) | T6: =IF(OR($A6="",N(C6)=0),"",S6-C6) | U6: =IF(OR($A6="",N(D6)=0),"",IF(S6>D6,"Over by "&TEXT(S6-D6,"#,##0"),"Within ceiling")) | V6: =IF(OR($A6="",N(O6)=0),"",(F6-COUNTIFS(Data!$C$2:$C$5001,$A6,Data!$R$2:$R$5001,1,Data!$Q$2:$Q$5001,1,Data!$W$2:$W$5001,"<12")+SUMIFS(Plan!$E$5:$E$304,Plan!$B$5:$B$304,$A6,Plan!$A$5:$A$304,"Hire",Plan!$D$5:$D$304,"Omani")-SUMIFS(Plan!$E$5:$E$304,Plan!$B$5:$B$304,$A6,Plan!$A$5:$A$304,"Exit",Plan!$D$5:$D$304,"Omani"))/O6)
E7: =IF($A7="","",COUNTIFS(Data!$C$2:$C$5001,$A7,Data!$R$2:$R$5001,1)) | F7: =IF($A7="","",COUNTIFS(Data!$C$2:$C$5001,$A7,Data!$R$2:$R$5001,1,Data!$Q$2:$Q$5001,1)) | G7: =IF(OR($A7="",N(E7)=0),"",F7/E7) | H7: =IF($A7="","",COUNTIFS(Data!$C$2:$C$5001,$A7,Data!$R$2:$R$5001,1,Data!$H$2:$H$5001,"F*")) | I7: =IF($A7="","",SUMIFS(Data!$AK$2:$AK$5001,Data!$C$2:$C$5001,$A7)) | J7: =IF($A7="","",COUNTIFS(Data!$C$2:$C$5001,$A7,Data!$R$2:$R$5001,1,Data!$W$2:$W$5001,"<12")) | K7: =IF($A7="","",COUNTIFS(Data!$C$2:$C$5001,$A7,Data!$U$2:$U$5001,">0")) | L7: =IF($A7="","",COUNTIFS(Data!$C$2:$C$5001,$A7,Data!$V$2:$V$5001,">0")) | M7: =IF($A7="","",SUMIFS(Plan!$E$5:$E$304,Plan!$B$5:$B$304,$A7,Plan!$A$5:$A$304,"Hire")) | N7: =IF($A7="","",SUMIFS(Plan!$E$5:$E$304,Plan!$B$5:$B$304,$A7,Plan!$A$5:$A$304,"Exit")) | O7: =IF($A7="","",E7-J7+M7-N7) | P7: =IF($A7="","",SUMIFS(Data!$AH$2:$AH$5001,Data!$C$2:$C$5001,$A7)) | Q7: =IF($A7="","",SUMIFS(Plan!$S$5:$S$304,Plan!$B$5:$B$304,$A7)) | R7: =IF($A7="","",(P7+Q7)*Contingency) | S7: =IF($A7="","",P7+Q7+R7) | T7: =IF(OR($A7="",N(C7)=0),"",S7-C7) | U7: =IF(OR($A7="",N(D7)=0),"",IF(S7>D7,"Over by "&TEXT(S7-D7,"#,##0"),"Within ceiling")) | V7: =IF(OR($A7="",N(O7)=0),"",(F7-COUNTIFS(Data!$C$2:$C$5001,$A7,Data!$R$2:$R$5001,1,Data!$Q$2:$Q$5001,1,Data!$W$2:$W$5001,"<12")+SUMIFS(Plan!$E$5:$E$304,Plan!$B$5:$B$304,$A7,Plan!$A$5:$A$304,"Hire",Plan!$D$5:$D$304,"Omani")-SUMIFS(Plan!$E$5:$E$304,Plan!$B$5:$B$304,$A7,Plan!$A$5:$A$304,"Exit",Plan!$D$5:$D$304,"Omani"))/O7)
E8: =IF($A8="","",COUNTIFS(Data!$C$2:$C$5001,$A8,Data!$R$2:$R$5001,1)) | F8: =IF($A8="","",COUNTIFS(Data!$C$2:$C$5001,$A8,Data!$R$2:$R$5001,1,Data!$Q$2:$Q$5001,1)) | G8: =IF(OR($A8="",N(E8)=0),"",F8/E8) | H8: =IF($A8="","",COUNTIFS(Data!$C$2:$C$5001,$A8,Data!$R$2:$R$5001,1,Data!$H$2:$H$5001,"F*")) | I8: =IF($A8="","",SUMIFS(Data!$AK$2:$AK$5001,Data!$C$2:$C$5001,$A8)) | J8: =IF($A8="","",COUNTIFS(Data!$C$2:$C$5001,$A8,Data!$R$2:$R$5001,1,Data!$W$2:$W$5001,"<12")) | K8: =IF($A8="","",COUNTIFS(Data!$C$2:$C$5001,$A8,Data!$U$2:$U$5001,">0")) | L8: =IF($A8="","",COUNTIFS(Data!$C$2:$C$5001,$A8,Data!$V$2:$V$5001,">0")) | M8: =IF($A8="","",SUMIFS(Plan!$E$5:$E$304,Plan!$B$5:$B$304,$A8,Plan!$A$5:$A$304,"Hire")) | N8: =IF($A8="","",SUMIFS(Plan!$E$5:$E$304,Plan!$B$5:$B$304,$A8,Plan!$A$5:$A$304,"Exit")) | O8: =IF($A8="","",E8-J8+M8-N8) | P8: =IF($A8="","",SUMIFS(Data!$AH$2:$AH$5001,Data!$C$2:$C$5001,$A8)) | Q8: =IF($A8="","",SUMIFS(Plan!$S$5:$S$304,Plan!$B$5:$B$304,$A8)) | R8: =IF($A8="","",(P8+Q8)*Contingency) | S8: =IF($A8="","",P8+Q8+R8) | T8: =IF(OR($A8="",N(C8)=0),"",S8-C8) | U8: =IF(OR($A8="",N(D8)=0),"",IF(S8>D8,"Over by "&TEXT(S8-D8,"#,##0"),"Within ceiling")) | V8: =IF(OR($A8="",N(O8)=0),"",(F8-COUNTIFS(Data!$C$2:$C$5001,$A8,Data!$R$2:$R$5001,1,Data!$Q$2:$Q$5001,1,Data!$W$2:$W$5001,"<12")+SUMIFS(Plan!$E$5:$E$304,Plan!$B$5:$B$304,$A8,Plan!$A$5:$A$304,"Hire",Plan!$D$5:$D$304,"Omani")-SUMIFS(Plan!$E$5:$E$304,Plan!$B$5:$B$304,$A8,Plan!$A$5:$A$304,"Exit",Plan!$D$5:$D$304,"Omani"))/O8)
E9: =IF($A9="","",COUNTIFS(Data!$C$2:$C$5001,$A9,Data!$R$2:$R$5001,1)) | F9: =IF($A9="","",COUNTIFS(Data!$C$2:$C$5001,$A9,Data!$R$2:$R$5001,1,Data!$Q$2:$Q$5001,1)) | G9: =IF(OR($A9="",N(E9)=0),"",F9/E9) | H9: =IF($A9="","",COUNTIFS(Data!$C$2:$C$5001,$A9,Data!$R$2:$R$5001,1,Data!$H$2:$H$5001,"F*")) | I9: =IF($A9="","",SUMIFS(Data!$AK$2:$AK$5001,Data!$C$2:$C$5001,$A9)) | J9: =IF($A9="","",COUNTIFS(Data!$C$2:$C$5001,$A9,Data!$R$2:$R$5001,1,Data!$W$2:$W$5001,"<12")) | K9: =IF($A9="","",COUNTIFS(Data!$C$2:$C$5001,$A9,Data!$U$2:$U$5001,">0")) | L9: =IF($A9="","",COUNTIFS(Data!$C$2:$C$5001,$A9,Data!$V$2:$V$5001,">0")) | M9: =IF($A9="","",SUMIFS(Plan!$E$5:$E$304,Plan!$B$5:$B$304,$A9,Plan!$A$5:$A$304,"Hire")) | N9: =IF($A9="","",SUMIFS(Plan!$E$5:$E$304,Plan!$B$5:$B$304,$A9,Plan!$A$5:$A$304,"Exit")) | O9: =IF($A9="","",E9-J9+M9-N9) | P9: =IF($A9="","",SUMIFS(Data!$AH$2:$AH$5001,Data!$C$2:$C$5001,$A9)) | Q9: =IF($A9="","",SUMIFS(Plan!$S$5:$S$304,Plan!$B$5:$B$304,$A9)) | R9: =IF($A9="","",(P9+Q9)*Contingency) | S9: =IF($A9="","",P9+Q9+R9) | T9: =IF(OR($A9="",N(C9)=0),"",S9-C9) | U9: =IF(OR($A9="",N(D9)=0),"",IF(S9>D9,"Over by "&TEXT(S9-D9,"#,##0"),"Within ceiling")) | V9: =IF(OR($A9="",N(O9)=0),"",(F9-COUNTIFS(Data!$C$2:$C$5001,$A9,Data!$R$2:$R$5001,1,Data!$Q$2:$Q$5001,1,Data!$W$2:$W$5001,"<12")+SUMIFS(Plan!$E$5:$E$304,Plan!$B$5:$B$304,$A9,Plan!$A$5:$A$304,"Hire",Plan!$D$5:$D$304,"Omani")-SUMIFS(Plan!$E$5:$E$304,Plan!$B$5:$B$304,$A9,Plan!$A$5:$A$304,"Exit",Plan!$D$5:$D$304,"Omani"))/O9)
E10: =IF($A10="","",COUNTIFS(Data!$C$2:$C$5001,$A10,Data!$R$2:$R$5001,1)) | F10: =IF($A10="","",COUNTIFS(Data!$C$2:$C$5001,$A10,Data!$R$2:$R$5001,1,Data!$Q$2:$Q$5001,1)) | G10: =IF(OR($A10="",N(E10)=0),"",F10/E10) | H10: =IF($A10="","",COUNTIFS(Data!$C$2:$C$5001,$A10,Data!$R$2:$R$5001,1,Data!$H$2:$H$5001,"F*")) | I10: =IF($A10="","",SUMIFS(Data!$AK$2:$AK$5001,Data!$C$2:$C$5001,$A10)) | J10: =IF($A10="","",COUNTIFS(Data!$C$2:$C$5001,$A10,Data!$R$2:$R$5001,1,Data!$W$2:$W$5001,"<12")) | K10: =IF($A10="","",COUNTIFS(Data!$C$2:$C$5001,$A10,Data!$U$2:$U$5001,">0")) | L10: =IF($A10="","",COUNTIFS(Data!$C$2:$C$5001,$A10,Data!$V$2:$V$5001,">0")) | M10: =IF($A10="","",SUMIFS(Plan!$E$5:$E$304,Plan!$B$5:$B$304,$A10,Plan!$A$5:$A$304,"Hire")) | N10: =IF($A10="","",SUMIFS(Plan!$E$5:$E$304,Plan!$B$5:$B$304,$A10,Plan!$A$5:$A$304,"Exit")) | O10: =IF($A10="","",E10-J10+M10-N10) | P10: =IF($A10="","",SUMIFS(Data!$AH$2:$AH$5001,Data!$C$2:$C$5001,$A10)) | Q10: =IF($A10="","",SUMIFS(Plan!$S$5:$S$304,Plan!$B$5:$B$304,$A10)) | R10: =IF($A10="","",(P10+Q10)*Contingency) | S10: =IF($A10="","",P10+Q10+R10) | T10: =IF(OR($A10="",N(C10)=0),"",S10-C10) | U10: =IF(OR($A10="",N(D10)=0),"",IF(S10>D10,"Over by "&TEXT(S10-D10,"#,##0"),"Within ceiling")) | V10: =IF(OR($A10="",N(O10)=0),"",(F10-COUNTIFS(Data!$C$2:$C$5001,$A10,Data!$R$2:$R$5001,1,Data!$Q$2:$Q$5001,1,Data!$W$2:$W$5001,"<12")+SUMIFS(Plan!$E$5:$E$304,Plan!$B$5:$B$304,$A10,Plan!$A$5:$A$304,"Hire",Plan!$D$5:$D$304,"Omani")-SUMIFS(Plan!$E$5:$E$304,Plan!$B$5:$B$304,$A10,Plan!$A$5:$A$304,"Exit",Plan!$D$5:$D$304,"Omani"))/O10)
E11: =IF($A11="","",COUNTIFS(Data!$C$2:$C$5001,$A11,Data!$R$2:$R$5001,1)) | F11: =IF($A11="","",COUNTIFS(Data!$C$2:$C$5001,$A11,Data!$R$2:$R$5001,1,Data!$Q$2:$Q$5001,1)) | G11: =IF(OR($A11="",N(E11)=0),"",F11/E11) | H11: =IF($A11="","",COUNTIFS(Data!$C$2:$C$5001,$A11,Data!$R$2:$R$5001,1,Data!$H$2:$H$5001,"F*")) | I11: =IF($A11="","",SUMIFS(Data!$AK$2:$AK$5001,Data!$C$2:$C$5001,$A11)) | J11: =IF($A11="","",COUNTIFS(Data!$C$2:$C$5001,$A11,Data!$R$2:$R$5001,1,Data!$W$2:$W$5001,"<12")) | K11: =IF($A11="","",COUNTIFS(Data!$C$2:$C$5001,$A11,Data!$U$2:$U$5001,">0")) | L11: =IF($A11="","",COUNTIFS(Data!$C$2:$C$5001,$A11,Data!$V$2:$V$5001,">0")) | M11: =IF($A11="","",SUMIFS(Plan!$E$5:$E$304,Plan!$B$5:$B$304,$A11,Plan!$A$5:$A$304,"Hire")) | N11: =IF($A11="","",SUMIFS(Plan!$E$5:$E$304,Plan!$B$5:$B$304,$A11,Plan!$A$5:$A$304,"Exit")) | O11: =IF($A11="","",E11-J11+M11-N11) | P11: =IF($A11="","",SUMIFS(Data!$AH$2:$AH$5001,Data!$C$2:$C$5001,$A11)) | Q11: =IF($A11="","",SUMIFS(Plan!$S$5:$S$304,Plan!$B$5:$B$304,$A11)) | R11: =IF($A11="","",(P11+Q11)*Contingency) | S11: =IF($A11="","",P11+Q11+R11) | T11: =IF(OR($A11="",N(C11)=0),"",S11-C11) | U11: =IF(OR($A11="",N(D11)=0),"",IF(S11>D11,"Over by "&TEXT(S11-D11,"#,##0"),"Within ceiling")) | V11: =IF(OR($A11="",N(O11)=0),"",(F11-COUNTIFS(Data!$C$2:$C$5001,$A11,Data!$R$2:$R$5001,1,Data!$Q$2:$Q$5001,1,Data!$W$2:$W$5001,"<12")+SUMIFS(Plan!$E$5:$E$304,Plan!$B$5:$B$304,$A11,Plan!$A$5:$A$304,"Hire",Plan!$D$5:$D$304,"Omani")-SUMIFS(Plan!$E$5:$E$304,Plan!$B$5:$B$304,$A11,Plan!$A$5:$A$304,"Exit",Plan!$D$5:$D$304,"Omani"))/O11)
E12: =IF($A12="","",COUNTIFS(Data!$C$2:$C$5001,$A12,Data!$R$2:$R$5001,1)) | F12: =IF($A12="","",COUNTIFS(Data!$C$2:$C$5001,$A12,Data!$R$2:$R$5001,1,Data!$Q$2:$Q$5001,1)) | G12: =IF(OR($A12="",N(E12)=0),"",F12/E12) | H12: =IF($A12="","",COUNTIFS(Data!$C$2:$C$5001,$A12,Data!$R$2:$R$5001,1,Data!$H$2:$H$5001,"F*")) | I12: =IF($A12="","",SUMIFS(Data!$AK$2:$AK$5001,Data!$C$2:$C$5001,$A12)) | J12: =IF($A12="","",COUNTIFS(Data!$C$2:$C$5001,$A12,Data!$R$2:$R$5001,1,Data!$W$2:$W$5001,"<12")) | K12: =IF($A12="","",COUNTIFS(Data!$C$2:$C$5001,$A12,Data!$U$2:$U$5001,">0")) | L12: =IF($A12="","",COUNTIFS(Data!$C$2:$C$5001,$A12,Data!$V$2:$V$5001,">0")) | M12: =IF($A12="","",SUMIFS(Plan!$E$5:$E$304,Plan!$B$5:$B$304,$A12,Plan!$A$5:$A$304,"Hire")) | N12: =IF($A12="","",SUMIFS(Plan!$E$5:$E$304,Plan!$B$5:$B$304,$A12,Plan!$A$5:$A$304,"Exit")) | O12: =IF($A12="","",E12-J12+M12-N12) | P12: =IF($A12="","",SUMIFS(Data!$AH$2:$AH$5001,Data!$C$2:$C$5001,$A12)) | Q12: =IF($A12="","",SUMIFS(Plan!$S$5:$S$304,Plan!$B$5:$B$304,$A12)) | R12: =IF($A12="","",(P12+Q12)*Contingency) | S12: =IF($A12="","",P12+Q12+R12) | T12: =IF(OR($A12="",N(C12)=0),"",S12-C12) | U12: =IF(OR($A12="",N(D12)=0),"",IF(S12>D12,"Over by "&TEXT(S12-D12,"#,##0"),"Within ceiling")) | V12: =IF(OR($A12="",N(O12)=0),"",(F12-COUNTIFS(Data!$C$2:$C$5001,$A12,Data!$R$2:$R$5001,1,Data!$Q$2:$Q$5001,1,Data!$W$2:$W$5001,"<12")+SUMIFS(Plan!$E$5:$E$304,Plan!$B$5:$B$304,$A12,Plan!$A$5:$A$304,"Hire",Plan!$D$5:$D$304,"Omani")-SUMIFS(Plan!$E$5:$E$304,Plan!$B$5:$B$304,$A12,Plan!$A$5:$A$304,"Exit",Plan!$D$5:$D$304,"Omani"))/O12)
E13: =IF($A13="","",COUNTIFS(Data!$C$2:$C$5001,$A13,Data!$R$2:$R$5001,1)) | F13: =IF($A13="","",COUNTIFS(Data!$C$2:$C$5001,$A13,Data!$R$2:$R$5001,1,Data!$Q$2:$Q$5001,1)) | G13: =IF(OR($A13="",N(E13)=0),"",F13/E13) | H13: =IF($A13="","",COUNTIFS(Data!$C$2:$C$5001,$A13,Data!$R$2:$R$5001,1,Data!$H$2:$H$5001,"F*")) | I13: =IF($A13="","",SUMIFS(Data!$AK$2:$AK$5001,Data!$C$2:$C$5001,$A13)) | J13: =IF($A13="","",COUNTIFS(Data!$C$2:$C$5001,$A13,Data!$R$2:$R$5001,1,Data!$W$2:$W$5001,"<12")) | K13: =IF($A13="","",COUNTIFS(Data!$C$2:$C$5001,$A13,Data!$U$2:$U$5001,">0")) | L13: =IF($A13="","",COUNTIFS(Data!$C$2:$C$5001,$A13,Data!$V$2:$V$5001,">0")) | M13: =IF($A13="","",SUMIFS(Plan!$E$5:$E$304,Plan!$B$5:$B$304,$A13,Plan!$A$5:$A$304,"Hire")) | N13: =IF($A13="","",SUMIFS(Plan!$E$5:$E$304,Plan!$B$5:$B$304,$A13,Plan!$A$5:$A$304,"Exit")) | O13: =IF($A13="","",E13-J13+M13-N13) | P13: =IF($A13="","",SUMIFS(Data!$AH$2:$AH$5001,Data!$C$2:$C$5001,$A13)) | Q13: =IF($A13="","",SUMIFS(Plan!$S$5:$S$304,Plan!$B$5:$B$304,$A13)) | R13: =IF($A13="","",(P13+Q13)*Contingency) | S13: =IF($A13="","",P13+Q13+R13) | T13: =IF(OR($A13="",N(C13)=0),"",S13-C13) | U13: =IF(OR($A13="",N(D13)=0),"",IF(S13>D13,"Over by "&TEXT(S13-D13,"#,##0"),"Within ceiling")) | V13: =IF(OR($A13="",N(O13)=0),"",(F13-COUNTIFS(Data!$C$2:$C$5001,$A13,Data!$R$2:$R$5001,1,Data!$Q$2:$Q$5001,1,Data!$W$2:$W$5001,"<12")+SUMIFS(Plan!$E$5:$E$304,Plan!$B$5:$B$304,$A13,Plan!$A$5:$A$304,"Hire",Plan!$D$5:$D$304,"Omani")-SUMIFS(Plan!$E$5:$E$304,Plan!$B$5:$B$304,$A13,Plan!$A$5:$A$304,"Exit",Plan!$D$5:$D$304,"Omani"))/O13)
E14: =IF($A14="","",COUNTIFS(Data!$C$2:$C$5001,$A14,Data!$R$2:$R$5001,1)) | F14: =IF($A14="","",COUNTIFS(Data!$C$2:$C$5001,$A14,Data!$R$2:$R$5001,1,Data!$Q$2:$Q$5001,1)) | G14: =IF(OR($A14="",N(E14)=0),"",F14/E14) | H14: =IF($A14="","",COUNTIFS(Data!$C$2:$C$5001,$A14,Data!$R$2:$R$5001,1,Data!$H$2:$H$5001,"F*")) | I14: =IF($A14="","",SUMIFS(Data!$AK$2:$AK$5001,Data!$C$2:$C$5001,$A14)) | J14: =IF($A14="","",COUNTIFS(Data!$C$2:$C$5001,$A14,Data!$R$2:$R$5001,1,Data!$W$2:$W$5001,"<12")) | K14: =IF($A14="","",COUNTIFS(Data!$C$2:$C$5001,$A14,Data!$U$2:$U$5001,">0")) | L14: =IF($A14="","",COUNTIFS(Data!$C$2:$C$5001,$A14,Data!$V$2:$V$5001,">0")) | M14: =IF($A14="","",SUMIFS(Plan!$E$5:$E$304,Plan!$B$5:$B$304,$A14,Plan!$A$5:$A$304,"Hire")) | N14: =IF($A14="","",SUMIFS(Plan!$E$5:$E$304,Plan!$B$5:$B$304,$A14,Plan!$A$5:$A$304,"Exit")) | O14: =IF($A14="","",E14-J14+M14-N14) | P14: =IF($A14="","",SUMIFS(Data!$AH$2:$AH$5001,Data!$C$2:$C$5001,$A14)) | Q14: =IF($A14="","",SUMIFS(Plan!$S$5:$S$304,Plan!$B$5:$B$304,$A14)) | R14: =IF($A14="","",(P14+Q14)*Contingency) | S14: =IF($A14="","",P14+Q14+R14) | T14: =IF(OR($A14="",N(C14)=0),"",S14-C14) | U14: =IF(OR($A14="",N(D14)=0),"",IF(S14>D14,"Over by "&TEXT(S14-D14,"#,##0"),"Within ceiling")) | V14: =IF(OR($A14="",N(O14)=0),"",(F14-COUNTIFS(Data!$C$2:$C$5001,$A14,Data!$R$2:$R$5001,1,Data!$Q$2:$Q$5001,1,Data!$W$2:$W$5001,"<12")+SUMIFS(Plan!$E$5:$E$304,Plan!$B$5:$B$304,$A14,Plan!$A$5:$A$304,"Hire",Plan!$D$5:$D$304,"Omani")-SUMIFS(Plan!$E$5:$E$304,Plan!$B$5:$B$304,$A14,Plan!$A$5:$A$304,"Exit",Plan!$D$5:$D$304,"Omani"))/O14)
E15: =IF($A15="","",COUNTIFS(Data!$C$2:$C$5001,$A15,Data!$R$2:$R$5001,1)) | F15: =IF($A15="","",COUNTIFS(Data!$C$2:$C$5001,$A15,Data!$R$2:$R$5001,1,Data!$Q$2:$Q$5001,1)) | G15: =IF(OR($A15="",N(E15)=0),"",F15/E15) | H15: =IF($A15="","",COUNTIFS(Data!$C$2:$C$5001,$A15,Data!$R$2:$R$5001,1,Data!$H$2:$H$5001,"F*")) | I15: =IF($A15="","",SUMIFS(Data!$AK$2:$AK$5001,Data!$C$2:$C$5001,$A15)) | J15: =IF($A15="","",COUNTIFS(Data!$C$2:$C$5001,$A15,Data!$R$2:$R$5001,1,Data!$W$2:$W$5001,"<12")) | K15: =IF($A15="","",COUNTIFS(Data!$C$2:$C$5001,$A15,Data!$U$2:$U$5001,">0")) | L15: =IF($A15="","",COUNTIFS(Data!$C$2:$C$5001,$A15,Data!$V$2:$V$5001,">0")) | M15: =IF($A15="","",SUMIFS(Plan!$E$5:$E$304,Plan!$B$5:$B$304,$A15,Plan!$A$5:$A$304,"Hire")) | N15: =IF($A15="","",SUMIFS(Plan!$E$5:$E$304,Plan!$B$5:$B$304,$A15,Plan!$A$5:$A$304,"Exit")) | O15: =IF($A15="","",E15-J15+M15-N15) | P15: =IF($A15="","",SUMIFS(Data!$AH$2:$AH$5001,Data!$C$2:$C$5001,$A15)) | Q15: =IF($A15="","",SUMIFS(Plan!$S$5:$S$304,Plan!$B$5:$B$304,$A15)) | R15: =IF($A15="","",(P15+Q15)*Contingency) | S15: =IF($A15="","",P15+Q15+R15) | T15: =IF(OR($A15="",N(C15)=0),"",S15-C15) | U15: =IF(OR($A15="",N(D15)=0),"",IF(S15>D15,"Over by "&TEXT(S15-D15,"#,##0"),"Within ceiling")) | V15: =IF(OR($A15="",N(O15)=0),"",(F15-COUNTIFS(Data!$C$2:$C$5001,$A15,Data!$R$2:$R$5001,1,Data!$Q$2:$Q$5001,1,Data!$W$2:$W$5001,"<12")+SUMIFS(Plan!$E$5:$E$304,Plan!$B$5:$B$304,$A15,Plan!$A$5:$A$304,"Hire",Plan!$D$5:$D$304,"Omani")-SUMIFS(Plan!$E$5:$E$304,Plan!$B$5:$B$304,$A15,Plan!$A$5:$A$304,"Exit",Plan!$D$5:$D$304,"Omani"))/O15)
E16: =IF($A16="","",COUNTIFS(Data!$C$2:$C$5001,$A16,Data!$R$2:$R$5001,1)) | F16: =IF($A16="","",COUNTIFS(Data!$C$2:$C$5001,$A16,Data!$R$2:$R$5001,1,Data!$Q$2:$Q$5001,1)) | G16: =IF(OR($A16="",N(E16)=0),"",F16/E16) | H16: =IF($A16="","",COUNTIFS(Data!$C$2:$C$5001,$A16,Data!$R$2:$R$5001,1,Data!$H$2:$H$5001,"F*")) | I16: =IF($A16="","",SUMIFS(Data!$AK$2:$AK$5001,Data!$C$2:$C$5001,$A16)) | J16: =IF($A16="","",COUNTIFS(Data!$C$2:$C$5001,$A16,Data!$R$2:$R$5001,1,Data!$W$2:$W$5001,"<12")) | K16: =IF($A16="","",COUNTIFS(Data!$C$2:$C$5001,$A16,Data!$U$2:$U$5001,">0")) | L16: =IF($A16="","",COUNTIFS(Data!$C$2:$C$5001,$A16,Data!$V$2:$V$5001,">0")) | M16: =IF($A16="","",SUMIFS(Plan!$E$5:$E$304,Plan!$B$5:$B$304,$A16,Plan!$A$5:$A$304,"Hire")) | N16: =IF($A16="","",SUMIFS(Plan!$E$5:$E$304,Plan!$B$5:$B$304,$A16,Plan!$A$5:$A$304,"Exit")) | O16: =IF($A16="","",E16-J16+M16-N16) | P16: =IF($A16="","",SUMIFS(Data!$AH$2:$AH$5001,Data!$C$2:$C$5001,$A16)) | Q16: =IF($A16="","",SUMIFS(Plan!$S$5:$S$304,Plan!$B$5:$B$304,$A16)) | R16: =IF($A16="","",(P16+Q16)*Contingency) | S16: =IF($A16="","",P16+Q16+R16) | T16: =IF(OR($A16="",N(C16)=0),"",S16-C16) | U16: =IF(OR($A16="",N(D16)=0),"",IF(S16>D16,"Over by "&TEXT(S16-D16,"#,##0"),"Within ceiling")) | V16: =IF(OR($A16="",N(O16)=0),"",(F16-COUNTIFS(Data!$C$2:$C$5001,$A16,Data!$R$2:$R$5001,1,Data!$Q$2:$Q$5001,1,Data!$W$2:$W$5001,"<12")+SUMIFS(Plan!$E$5:$E$304,Plan!$B$5:$B$304,$A16,Plan!$A$5:$A$304,"Hire",Plan!$D$5:$D$304,"Omani")-SUMIFS(Plan!$E$5:$E$304,Plan!$B$5:$B$304,$A16,Plan!$A$5:$A$304,"Exit",Plan!$D$5:$D$304,"Omani"))/O16)
... E54: =IF($A54="","",COUNTIFS(Data!$C$2:$C$5001,$A54,Data!$R$2:$R$5001,1)) | F54: =IF($A54="","",COUNTIFS(Data!$C$2:$C$5001,$A54,Data!$R$2:$R$5001,1,Data!$Q$2:$Q$5001,1)) | G54: =IF(OR($A54="",N(E54)=0),"",F54/E54) | H54: =IF($A54="","",COUNTIFS(Data!$C$2:$C$5001,$A54,Data!$R$2:$R$5001,1,Data!$H$2:$H$5001,"F*")) | I54: =IF($A54="","",SUMIFS(Data!$AK$2:$AK$5001,Data!$C$2:$C$5001,$A54)) | J54: =IF($A54="","",COUNTIFS(Data!$C$2:$C$5001,$A54,Data!$R$2:$R$5001,1,Data!$W$2:$W$5001,"<12")) | K54: =IF($A54="","",COUNTIFS(Data!$C$2:$C$5001,$A54,Data!$U$2:$U$5001,">0")) | L54: =IF($A54="","",COUNTIFS(Data!$C$2:$C$5001,$A54,Data!$V$2:$V$5001,">0")) | M54: =IF($A54="","",SUMIFS(Plan!$E$5:$E$304,Plan!$B$5:$B$304,$A54,Plan!$A$5:$A$304,"Hire")) | N54: =IF($A54="","",SUMIFS(Plan!$E$5:$E$304,Plan!$B$5:$B$304,$A54,Plan!$A$5:$A$304,"Exit")) | O54: =IF($A54="","",E54-J54+M54-N54) | P54: =IF($A54="","",SUMIFS(Data!$AH$2:$AH$5001,Data!$C$2:$C$5001,$A54)) | Q54: =IF($A54="","",SUMIFS(Plan!$S$5:$S$304,Plan!$B$5:$B$304,$A54)) | R54: =IF($A54="","",(P54+Q54)*Contingency) | S54: =IF($A54="","",P54+Q54+R54) | T54: =IF(OR($A54="",N(C54)=0),"",S54-C54) | U54: =IF(OR($A54="",N(D54)=0),"",IF(S54>D54,"Over by "&TEXT(S54-D54,"#,##0"),"Within ceiling")) | V54: =IF(OR($A54="",N(O54)=0),"",(F54-COUNTIFS(Data!$C$2:$C$5001,$A54,Data!$R$2:$R$5001,1,Data!$Q$2:$Q$5001,1,Data!$W$2:$W$5001,"<12")+SUMIFS(Plan!$E$5:$E$304,Plan!$B$5:$B$304,$A54,Plan!$A$5:$A$304,"Hire",Plan!$D$5:$D$304,"Omani")-SUMIFS(Plan!$E$5:$E$304,Plan!$B$5:$B$304,$A54,Plan!$A$5:$A$304,"Exit",Plan!$D$5:$D$304,"Omani"))/O54)
A55: Total | C55: =SUM(C5:C54) | D55: =SUM(D5:D54) | E55: =SUM(E5:E54) | F55: =SUM(F5:F54) | G55: =IF(E55=0,"",F55/E55) | H55: =SUM(H5:H54) | I55: =SUM(I5:I54) | J55: =SUM(J5:J54) | K55: =SUM(K5:K54) | L55: =SUM(L5:L54) | M55: =SUM(M5:M54) | N55: =SUM(N5:N54) | O55: =SUM(O5:O54) | ... T55: =SUM(T5:T54) | V55: =IF(O55=0,"",(F55-COUNTIFS(Data!$R$2:$R$5001,1,Data!$Q$2:$Q$5001,1,Data!$W$2:$W$5001,"<12")+SUMIFS(Plan!$E$5:$E$304,Plan!$A$5:$A$304,"Hire",Plan!$D$5:$D$304,"Omani")-SUMIFS(Plan!$E$5:$E$304,Plan!$A$5:$A$304,"Exit",Plan!$D$5:$D$304,"Omani"))/O55)

Sheet Data
A1: Employee ID | B1: Employee name | C1: Department * | D1: Section | E1: Job title | F1: Grade | G1: Nationality * | H1: Gender | I1: Date of birth | J1: Joining date | K1: Contract end date | L1: Basic salary (OMR / month) * | M1: Allowances total (OMR / month) | N1: Employment status | O1: Planned exit month (1-12, optional) | P1: Personal increment % (optional) | Q1: Omani (1/0) | R1: Active (1/0) | S1: Age at 1 Jan FY | T1: Service (years) | U1: Retirement month in FY (0 = none) | V1: Contract end month in FY (0 = none) | W1: Last month on payroll (0 = not active) | X1: Increment rate used | Y1: Paid months incl. increment | Z1: Department overtime % | AA1: Annual basic (OMR) | AB1: Annual allowances (OMR) | AC1: Overtime (OMR) | AD1: Bonus (OMR) | AE1: Social protection (OMR) | AF1: End of service (OMR) | AG1: Tickets, medical & training (OMR) | AH1: FY cost (OMR) | AI1: Run-rate cost: 12 months, no increment (OMR) | AJ1: Full-year cost with increment (OMR) | AK1: Monthly gross today (OMR) | AL1: Check | AM1: Monthly cost rate before increment (OMR) | AN1: Monthly per-head costs (OMR)
Q2: =IF($C2="",0,IF(OR(LOWER(TRIM($G2))="omani",LOWER(TRIM($G2))="oman",LOWER(TRIM($G2))="om",LOWER(TRIM($G2))="local"),1,0)) | R2: =IF($C2="",0,IF(OR(ISNUMBER(SEARCH("resign",$N2)),ISNUMBER(SEARCH("terminat",$N2)),ISNUMBER(SEARCH("inactive",$N2)),ISNUMBER(SEARCH("vacan",$N2)),ISNUMBER(SEARCH("deceased",$N2)),ISNUMBER(SEARCH("separated",$N2))),0,1)) | S2: =IF(OR($R2=0,NOT(ISNUMBER($I2))),"",IFERROR(DATEDIF($I2,DATE(FY,1,1),"y"),"")) | T2: =IF(OR($R2=0,NOT(ISNUMBER($J2))),"",IFERROR(DATEDIF($J2,DATE(FY,1,1),"y"),0)) | U2: =IF(OR($R2=0,NOT(ISNUMBER($I2))),0,IF(YEAR($I2)+IF($Q2=1,RetAgeO,RetAgeE)=FY,MONTH($I2),IF(YEAR($I2)+IF($Q2=1,RetAgeO,RetAgeE)<FY,1,0))) | V2: =IF(OR($R2=0,NOT(ISNUMBER($K2))),0,IF(YEAR($K2)=FY,MONTH($K2),IF(YEAR($K2)<FY,1,0))) | W2: =IF($R2=0,0,MIN(12,IF(AND(ISNUMBER($O2),$O2>=1,$O2<=12),INT($O2),12),IF(AND(RetireExit="Yes",$U2>0),$U2,12),IF(AND(ContractExit="Yes",$V2>0),$V2,12))) | X2: =IF(ISNUMBER($P2),$P2,IncPct) | Y2: =IF($W2=0,0,MAX(0,MIN($W2,IncMonth-1))+MAX(0,$W2-IncMonth+1)*(1+$X2)) | Z2: =IF($C2="",0,IFERROR(INDEX(Departments!$B$5:$B$54,MATCH($C2,Departments!$A$5:$A$54,0)),0)) | AA2: =N($L2)*$Y2 | AB2: =N($M2)*$Y2 | AC2: =$AA2*$Z2 | AD2: =$AA2*BonusMonths/12 | AE2: =($AA2+SI_Gross*$AB2)*IF($Q2=1,SI_O,SI_E) | AF2: =IF($Q2=1,0,$AA2*EOSB) | AG2: =$AN2*$W2 | AH2: =SUM($AA2:$AG2) | AI2: =12*($AM2+$AN2) | AJ2: =$AM2*((IncMonth-1)+(13-IncMonth)*(1+$X2))+12*$AN2 | AK2: =IF($R2=1,N($L2)+N($M2),0) | AL2: =IF($C2="","",IF(N($L2)<=0,"Basic salary missing",IF(ISNA(MATCH($C2,Departments!$A$5:$A$54,0)),"Department not on Departments sheet",IF(AND($I2<>"",NOT(ISNUMBER($I2))),"Date of birth is text, not a date",IF(AND($K2<>"",NOT(ISNUMBER($K2))),"Contract end is text, not a date",""))))) | AM2: =IF($R2=0,0,N($L2)*(1+$Z2+BonusMonths/12+IF($Q2=1,0,EOSB))+N($M2)+(N($L2)+SI_Gross*N($M2))*IF($Q2=1,SI_O,SI_E)) | AN2: =IF($R2=0,0,(IF($Q2=1,MedO,MedE+Ticket)+Training)/12)
Q3: =IF($C3="",0,IF(OR(LOWER(TRIM($G3))="omani",LOWER(TRIM($G3))="oman",LOWER(TRIM($G3))="om",LOWER(TRIM($G3))="local"),1,0)) | R3: =IF($C3="",0,IF(OR(ISNUMBER(SEARCH("resign",$N3)),ISNUMBER(SEARCH("terminat",$N3)),ISNUMBER(SEARCH("inactive",$N3)),ISNUMBER(SEARCH("vacan",$N3)),ISNUMBER(SEARCH("deceased",$N3)),ISNUMBER(SEARCH("separated",$N3))),0,1)) | S3: =IF(OR($R3=0,NOT(ISNUMBER($I3))),"",IFERROR(DATEDIF($I3,DATE(FY,1,1),"y"),"")) | T3: =IF(OR($R3=0,NOT(ISNUMBER($J3))),"",IFERROR(DATEDIF($J3,DATE(FY,1,1),"y"),0)) | U3: =IF(OR($R3=0,NOT(ISNUMBER($I3))),0,IF(YEAR($I3)+IF($Q3=1,RetAgeO,RetAgeE)=FY,MONTH($I3),IF(YEAR($I3)+IF($Q3=1,RetAgeO,RetAgeE)<FY,1,0))) | V3: =IF(OR($R3=0,NOT(ISNUMBER($K3))),0,IF(YEAR($K3)=FY,MONTH($K3),IF(YEAR($K3)<FY,1,0))) | W3: =IF($R3=0,0,MIN(12,IF(AND(ISNUMBER($O3),$O3>=1,$O3<=12),INT($O3),12),IF(AND(RetireExit="Yes",$U3>0),$U3,12),IF(AND(ContractExit="Yes",$V3>0),$V3,12))) | X3: =IF(ISNUMBER($P3),$P3,IncPct) | Y3: =IF($W3=0,0,MAX(0,MIN($W3,IncMonth-1))+MAX(0,$W3-IncMonth+1)*(1+$X3)) | Z3: =IF($C3="",0,IFERROR(INDEX(Departments!$B$5:$B$54,MATCH($C3,Departments!$A$5:$A$54,0)),0)) | AA3: =N($L3)*$Y3 | AB3: =N($M3)*$Y3 | AC3: =$AA3*$Z3 | AD3: =$AA3*BonusMonths/12 | AE3: =($AA3+SI_Gross*$AB3)*IF($Q3=1,SI_O,SI_E) | AF3: =IF($Q3=1,0,$AA3*EOSB) | AG3: =$AN3*$W3 | AH3: =SUM($AA3:$AG3) | AI3: =12*($AM3+$AN3) | AJ3: =$AM3*((IncMonth-1)+(13-IncMonth)*(1+$X3))+12*$AN3 | AK3: =IF($R3=1,N($L3)+N($M3),0) | AL3: =IF($C3="","",IF(N($L3)<=0,"Basic salary missing",IF(ISNA(MATCH($C3,Departments!$A$5:$A$54,0)),"Department not on Departments sheet",IF(AND($I3<>"",NOT(ISNUMBER($I3))),"Date of birth is text, not a date",IF(AND($K3<>"",NOT(ISNUMBER($K3))),"Contract end is text, not a date",""))))) | AM3: =IF($R3=0,0,N($L3)*(1+$Z3+BonusMonths/12+IF($Q3=1,0,EOSB))+N($M3)+(N($L3)+SI_Gross*N($M3))*IF($Q3=1,SI_O,SI_E)) | AN3: =IF($R3=0,0,(IF($Q3=1,MedO,MedE+Ticket)+Training)/12)
Q4: =IF($C4="",0,IF(OR(LOWER(TRIM($G4))="omani",LOWER(TRIM($G4))="oman",LOWER(TRIM($G4))="om",LOWER(TRIM($G4))="local"),1,0)) | R4: =IF($C4="",0,IF(OR(ISNUMBER(SEARCH("resign",$N4)),ISNUMBER(SEARCH("terminat",$N4)),ISNUMBER(SEARCH("inactive",$N4)),ISNUMBER(SEARCH("vacan",$N4)),ISNUMBER(SEARCH("deceased",$N4)),ISNUMBER(SEARCH("separated",$N4))),0,1)) | S4: =IF(OR($R4=0,NOT(ISNUMBER($I4))),"",IFERROR(DATEDIF($I4,DATE(FY,1,1),"y"),"")) | T4: =IF(OR($R4=0,NOT(ISNUMBER($J4))),"",IFERROR(DATEDIF($J4,DATE(FY,1,1),"y"),0)) | U4: =IF(OR($R4=0,NOT(ISNUMBER($I4))),0,IF(YEAR($I4)+IF($Q4=1,RetAgeO,RetAgeE)=FY,MONTH($I4),IF(YEAR($I4)+IF($Q4=1,RetAgeO,RetAgeE)<FY,1,0))) | V4: =IF(OR($R4=0,NOT(ISNUMBER($K4))),0,IF(YEAR($K4)=FY,MONTH($K4),IF(YEAR($K4)<FY,1,0))) | W4: =IF($R4=0,0,MIN(12,IF(AND(ISNUMBER($O4),$O4>=1,$O4<=12),INT($O4),12),IF(AND(RetireExit="Yes",$U4>0),$U4,12),IF(AND(ContractExit="Yes",$V4>0),$V4,12))) | X4: =IF(ISNUMBER($P4),$P4,IncPct) | Y4: =IF($W4=0,0,MAX(0,MIN($W4,IncMonth-1))+MAX(0,$W4-IncMonth+1)*(1+$X4)) | Z4: =IF($C4="",0,IFERROR(INDEX(Departments!$B$5:$B$54,MATCH($C4,Departments!$A$5:$A$54,0)),0)) | AA4: =N($L4)*$Y4 | AB4: =N($M4)*$Y4 | AC4: =$AA4*$Z4 | AD4: =$AA4*BonusMonths/12 | AE4: =($AA4+SI_Gross*$AB4)*IF($Q4=1,SI_O,SI_E) | AF4: =IF($Q4=1,0,$AA4*EOSB) | AG4: =$AN4*$W4 | AH4: =SUM($AA4:$AG4) | AI4: =12*($AM4+$AN4) | AJ4: =$AM4*((IncMonth-1)+(13-IncMonth)*(1+$X4))+12*$AN4 | AK4: =IF($R4=1,N($L4)+N($M4),0) | AL4: =IF($C4="","",IF(N($L4)<=0,"Basic salary missing",IF(ISNA(MATCH($C4,Departments!$A$5:$A$54,0)),"Department not on Departments sheet",IF(AND($I4<>"",NOT(ISNUMBER($I4))),"Date of birth is text, not a date",IF(AND($K4<>"",NOT(ISNUMBER($K4))),"Contract end is text, not a date",""))))) | AM4: =IF($R4=0,0,N($L4)*(1+$Z4+BonusMonths/12+IF($Q4=1,0,EOSB))+N($M4)+(N($L4)+SI_Gross*N($M4))*IF($Q4=1,SI_O,SI_E)) | AN4: =IF($R4=0,0,(IF($Q4=1,MedO,MedE+Ticket)+Training)/12)
Q5: =IF($C5="",0,IF(OR(LOWER(TRIM($G5))="omani",LOWER(TRIM($G5))="oman",LOWER(TRIM($G5))="om",LOWER(TRIM($G5))="local"),1,0)) | R5: =IF($C5="",0,IF(OR(ISNUMBER(SEARCH("resign",$N5)),ISNUMBER(SEARCH("terminat",$N5)),ISNUMBER(SEARCH("inactive",$N5)),ISNUMBER(SEARCH("vacan",$N5)),ISNUMBER(SEARCH("deceased",$N5)),ISNUMBER(SEARCH("separated",$N5))),0,1)) | S5: =IF(OR($R5=0,NOT(ISNUMBER($I5))),"",IFERROR(DATEDIF($I5,DATE(FY,1,1),"y"),"")) | T5: =IF(OR($R5=0,NOT(ISNUMBER($J5))),"",IFERROR(DATEDIF($J5,DATE(FY,1,1),"y"),0)) | U5: =IF(OR($R5=0,NOT(ISNUMBER($I5))),0,IF(YEAR($I5)+IF($Q5=1,RetAgeO,RetAgeE)=FY,MONTH($I5),IF(YEAR($I5)+IF($Q5=1,RetAgeO,RetAgeE)<FY,1,0))) | V5: =IF(OR($R5=0,NOT(ISNUMBER($K5))),0,IF(YEAR($K5)=FY,MONTH($K5),IF(YEAR($K5)<FY,1,0))) | W5: =IF($R5=0,0,MIN(12,IF(AND(ISNUMBER($O5),$O5>=1,$O5<=12),INT($O5),12),IF(AND(RetireExit="Yes",$U5>0),$U5,12),IF(AND(ContractExit="Yes",$V5>0),$V5,12))) | X5: =IF(ISNUMBER($P5),$P5,IncPct) | Y5: =IF($W5=0,0,MAX(0,MIN($W5,IncMonth-1))+MAX(0,$W5-IncMonth+1)*(1+$X5)) | Z5: =IF($C5="",0,IFERROR(INDEX(Departments!$B$5:$B$54,MATCH($C5,Departments!$A$5:$A$54,0)),0)) | AA5: =N($L5)*$Y5 | AB5: =N($M5)*$Y5 | AC5: =$AA5*$Z5 | AD5: =$AA5*BonusMonths/12 | AE5: =($AA5+SI_Gross*$AB5)*IF($Q5=1,SI_O,SI_E) | AF5: =IF($Q5=1,0,$AA5*EOSB) | AG5: =$AN5*$W5 | AH5: =SUM($AA5:$AG5) | AI5: =12*($AM5+$AN5) | AJ5: =$AM5*((IncMonth-1)+(13-IncMonth)*(1+$X5))+12*$AN5 | AK5: =IF($R5=1,N($L5)+N($M5),0) | AL5: =IF($C5="","",IF(N($L5)<=0,"Basic salary missing",IF(ISNA(MATCH($C5,Departments!$A$5:$A$54,0)),"Department not on Departments sheet",IF(AND($I5<>"",NOT(ISNUMBER($I5))),"Date of birth is text, not a date",IF(AND($K5<>"",NOT(ISNUMBER($K5))),"Contract end is text, not a date",""))))) | AM5: =IF($R5=0,0,N($L5)*(1+$Z5+BonusMonths/12+IF($Q5=1,0,EOSB))+N($M5)+(N($L5)+SI_Gross*N($M5))*IF($Q5=1,SI_O,SI_E)) | AN5: =IF($R5=0,0,(IF($Q5=1,MedO,MedE+Ticket)+Training)/12)
Q6: =IF($C6="",0,IF(OR(LOWER(TRIM($G6))="omani",LOWER(TRIM($G6))="oman",LOWER(TRIM($G6))="om",LOWER(TRIM($G6))="local"),1,0)) | R6: =IF($C6="",0,IF(OR(ISNUMBER(SEARCH("resign",$N6)),ISNUMBER(SEARCH("terminat",$N6)),ISNUMBER(SEARCH("inactive",$N6)),ISNUMBER(SEARCH("vacan",$N6)),ISNUMBER(SEARCH("deceased",$N6)),ISNUMBER(SEARCH("separated",$N6))),0,1)) | S6: =IF(OR($R6=0,NOT(ISNUMBER($I6))),"",IFERROR(DATEDIF($I6,DATE(FY,1,1),"y"),"")) | T6: =IF(OR($R6=0,NOT(ISNUMBER($J6))),"",IFERROR(DATEDIF($J6,DATE(FY,1,1),"y"),0)) | U6: =IF(OR($R6=0,NOT(ISNUMBER($I6))),0,IF(YEAR($I6)+IF($Q6=1,RetAgeO,RetAgeE)=FY,MONTH($I6),IF(YEAR($I6)+IF($Q6=1,RetAgeO,RetAgeE)<FY,1,0))) | V6: =IF(OR($R6=0,NOT(ISNUMBER($K6))),0,IF(YEAR($K6)=FY,MONTH($K6),IF(YEAR($K6)<FY,1,0))) | W6: =IF($R6=0,0,MIN(12,IF(AND(ISNUMBER($O6),$O6>=1,$O6<=12),INT($O6),12),IF(AND(RetireExit="Yes",$U6>0),$U6,12),IF(AND(ContractExit="Yes",$V6>0),$V6,12))) | X6: =IF(ISNUMBER($P6),$P6,IncPct) | Y6: =IF($W6=0,0,MAX(0,MIN($W6,IncMonth-1))+MAX(0,$W6-IncMonth+1)*(1+$X6)) | Z6: =IF($C6="",0,IFERROR(INDEX(Departments!$B$5:$B$54,MATCH($C6,Departments!$A$5:$A$54,0)),0)) | AA6: =N($L6)*$Y6 | AB6: =N($M6)*$Y6 | AC6: =$AA6*$Z6 | AD6: =$AA6*BonusMonths/12 | AE6: =($AA6+SI_Gross*$AB6)*IF($Q6=1,SI_O,SI_E) | AF6: =IF($Q6=1,0,$AA6*EOSB) | AG6: =$AN6*$W6 | AH6: =SUM($AA6:$AG6) | AI6: =12*($AM6+$AN6) | AJ6: =$AM6*((IncMonth-1)+(13-IncMonth)*(1+$X6))+12*$AN6 | AK6: =IF($R6=1,N($L6)+N($M6),0) | AL6: =IF($C6="","",IF(N($L6)<=0,"Basic salary missing",IF(ISNA(MATCH($C6,Departments!$A$5:$A$54,0)),"Department not on Departments sheet",IF(AND($I6<>"",NOT(ISNUMBER($I6))),"Date of birth is text, not a date",IF(AND($K6<>"",NOT(ISNUMBER($K6))),"Contract end is text, not a date",""))))) | AM6: =IF($R6=0,0,N($L6)*(1+$Z6+BonusMonths/12+IF($Q6=1,0,EOSB))+N($M6)+(N($L6)+SI_Gross*N($M6))*IF($Q6=1,SI_O,SI_E)) | AN6: =IF($R6=0,0,(IF($Q6=1,MedO,MedE+Ticket)+Training)/12)
Q7: =IF($C7="",0,IF(OR(LOWER(TRIM($G7))="omani",LOWER(TRIM($G7))="oman",LOWER(TRIM($G7))="om",LOWER(TRIM($G7))="local"),1,0)) | R7: =IF($C7="",0,IF(OR(ISNUMBER(SEARCH("resign",$N7)),ISNUMBER(SEARCH("terminat",$N7)),ISNUMBER(SEARCH("inactive",$N7)),ISNUMBER(SEARCH("vacan",$N7)),ISNUMBER(SEARCH("deceased",$N7)),ISNUMBER(SEARCH("separated",$N7))),0,1)) | S7: =IF(OR($R7=0,NOT(ISNUMBER($I7))),"",IFERROR(DATEDIF($I7,DATE(FY,1,1),"y"),"")) | T7: =IF(OR($R7=0,NOT(ISNUMBER($J7))),"",IFERROR(DATEDIF($J7,DATE(FY,1,1),"y"),0)) | U7: =IF(OR($R7=0,NOT(ISNUMBER($I7))),0,IF(YEAR($I7)+IF($Q7=1,RetAgeO,RetAgeE)=FY,MONTH($I7),IF(YEAR($I7)+IF($Q7=1,RetAgeO,RetAgeE)<FY,1,0))) | V7: =IF(OR($R7=0,NOT(ISNUMBER($K7))),0,IF(YEAR($K7)=FY,MONTH($K7),IF(YEAR($K7)<FY,1,0))) | W7: =IF($R7=0,0,MIN(12,IF(AND(ISNUMBER($O7),$O7>=1,$O7<=12),INT($O7),12),IF(AND(RetireExit="Yes",$U7>0),$U7,12),IF(AND(ContractExit="Yes",$V7>0),$V7,12))) | X7: =IF(ISNUMBER($P7),$P7,IncPct) | Y7: =IF($W7=0,0,MAX(0,MIN($W7,IncMonth-1))+MAX(0,$W7-IncMonth+1)*(1+$X7)) | Z7: =IF($C7="",0,IFERROR(INDEX(Departments!$B$5:$B$54,MATCH($C7,Departments!$A$5:$A$54,0)),0)) | AA7: =N($L7)*$Y7 | AB7: =N($M7)*$Y7 | AC7: =$AA7*$Z7 | AD7: =$AA7*BonusMonths/12 | AE7: =($AA7+SI_Gross*$AB7)*IF($Q7=1,SI_O,SI_E) | AF7: =IF($Q7=1,0,$AA7*EOSB) | AG7: =$AN7*$W7 | AH7: =SUM($AA7:$AG7) | AI7: =12*($AM7+$AN7) | AJ7: =$AM7*((IncMonth-1)+(13-IncMonth)*(1+$X7))+12*$AN7 | AK7: =IF($R7=1,N($L7)+N($M7),0) | AL7: =IF($C7="","",IF(N($L7)<=0,"Basic salary missing",IF(ISNA(MATCH($C7,Departments!$A$5:$A$54,0)),"Department not on Departments sheet",IF(AND($I7<>"",NOT(ISNUMBER($I7))),"Date of birth is text, not a date",IF(AND($K7<>"",NOT(ISNUMBER($K7))),"Contract end is text, not a date",""))))) | AM7: =IF($R7=0,0,N($L7)*(1+$Z7+BonusMonths/12+IF($Q7=1,0,EOSB))+N($M7)+(N($L7)+SI_Gross*N($M7))*IF($Q7=1,SI_O,SI_E)) | AN7: =IF($R7=0,0,(IF($Q7=1,MedO,MedE+Ticket)+Training)/12)
Q8: =IF($C8="",0,IF(OR(LOWER(TRIM($G8))="omani",LOWER(TRIM($G8))="oman",LOWER(TRIM($G8))="om",LOWER(TRIM($G8))="local"),1,0)) | R8: =IF($C8="",0,IF(OR(ISNUMBER(SEARCH("resign",$N8)),ISNUMBER(SEARCH("terminat",$N8)),ISNUMBER(SEARCH("inactive",$N8)),ISNUMBER(SEARCH("vacan",$N8)),ISNUMBER(SEARCH("deceased",$N8)),ISNUMBER(SEARCH("separated",$N8))),0,1)) | S8: =IF(OR($R8=0,NOT(ISNUMBER($I8))),"",IFERROR(DATEDIF($I8,DATE(FY,1,1),"y"),"")) | T8: =IF(OR($R8=0,NOT(ISNUMBER($J8))),"",IFERROR(DATEDIF($J8,DATE(FY,1,1),"y"),0)) | U8: =IF(OR($R8=0,NOT(ISNUMBER($I8))),0,IF(YEAR($I8)+IF($Q8=1,RetAgeO,RetAgeE)=FY,MONTH($I8),IF(YEAR($I8)+IF($Q8=1,RetAgeO,RetAgeE)<FY,1,0))) | V8: =IF(OR($R8=0,NOT(ISNUMBER($K8))),0,IF(YEAR($K8)=FY,MONTH($K8),IF(YEAR($K8)<FY,1,0))) | W8: =IF($R8=0,0,MIN(12,IF(AND(ISNUMBER($O8),$O8>=1,$O8<=12),INT($O8),12),IF(AND(RetireExit="Yes",$U8>0),$U8,12),IF(AND(ContractExit="Yes",$V8>0),$V8,12))) | X8: =IF(ISNUMBER($P8),$P8,IncPct) | Y8: =IF($W8=0,0,MAX(0,MIN($W8,IncMonth-1))+MAX(0,$W8-IncMonth+1)*(1+$X8)) | Z8: =IF($C8="",0,IFERROR(INDEX(Departments!$B$5:$B$54,MATCH($C8,Departments!$A$5:$A$54,0)),0)) | AA8: =N($L8)*$Y8 | AB8: =N($M8)*$Y8 | AC8: =$AA8*$Z8 | AD8: =$AA8*BonusMonths/12 | AE8: =($AA8+SI_Gross*$AB8)*IF($Q8=1,SI_O,SI_E) | AF8: =IF($Q8=1,0,$AA8*EOSB) | AG8: =$AN8*$W8 | AH8: =SUM($AA8:$AG8) | AI8: =12*($AM8+$AN8) | AJ8: =$AM8*((IncMonth-1)+(13-IncMonth)*(1+$X8))+12*$AN8 | AK8: =IF($R8=1,N($L8)+N($M8),0) | AL8: =IF($C8="","",IF(N($L8)<=0,"Basic salary missing",IF(ISNA(MATCH($C8,Departments!$A$5:$A$54,0)),"Department not on Departments sheet",IF(AND($I8<>"",NOT(ISNUMBER($I8))),"Date of birth is text, not a date",IF(AND($K8<>"",NOT(ISNUMBER($K8))),"Contract end is text, not a date",""))))) | AM8: =IF($R8=0,0,N($L8)*(1+$Z8+BonusMonths/12+IF($Q8=1,0,EOSB))+N($M8)+(N($L8)+SI_Gross*N($M8))*IF($Q8=1,SI_O,SI_E)) | AN8: =IF($R8=0,0,(IF($Q8=1,MedO,MedE+Ticket)+Training)/12)
Q9: =IF($C9="",0,IF(OR(LOWER(TRIM($G9))="omani",LOWER(TRIM($G9))="oman",LOWER(TRIM($G9))="om",LOWER(TRIM($G9))="local"),1,0)) | R9: =IF($C9="",0,IF(OR(ISNUMBER(SEARCH("resign",$N9)),ISNUMBER(SEARCH("terminat",$N9)),ISNUMBER(SEARCH("inactive",$N9)),ISNUMBER(SEARCH("vacan",$N9)),ISNUMBER(SEARCH("deceased",$N9)),ISNUMBER(SEARCH("separated",$N9))),0,1)) | S9: =IF(OR($R9=0,NOT(ISNUMBER($I9))),"",IFERROR(DATEDIF($I9,DATE(FY,1,1),"y"),"")) | T9: =IF(OR($R9=0,NOT(ISNUMBER($J9))),"",IFERROR(DATEDIF($J9,DATE(FY,1,1),"y"),0)) | U9: =IF(OR($R9=0,NOT(ISNUMBER($I9))),0,IF(YEAR($I9)+IF($Q9=1,RetAgeO,RetAgeE)=FY,MONTH($I9),IF(YEAR($I9)+IF($Q9=1,RetAgeO,RetAgeE)<FY,1,0))) | V9: =IF(OR($R9=0,NOT(ISNUMBER($K9))),0,IF(YEAR($K9)=FY,MONTH($K9),IF(YEAR($K9)<FY,1,0))) | W9: =IF($R9=0,0,MIN(12,IF(AND(ISNUMBER($O9),$O9>=1,$O9<=12),INT($O9),12),IF(AND(RetireExit="Yes",$U9>0),$U9,12),IF(AND(ContractExit="Yes",$V9>0),$V9,12))) | X9: =IF(ISNUMBER($P9),$P9,IncPct) | Y9: =IF($W9=0,0,MAX(0,MIN($W9,IncMonth-1))+MAX(0,$W9-IncMonth+1)*(1+$X9)) | Z9: =IF($C9="",0,IFERROR(INDEX(Departments!$B$5:$B$54,MATCH($C9,Departments!$A$5:$A$54,0)),0)) | AA9: =N($L9)*$Y9 | AB9: =N($M9)*$Y9 | AC9: =$AA9*$Z9 | AD9: =$AA9*BonusMonths/12 | AE9: =($AA9+SI_Gross*$AB9)*IF($Q9=1,SI_O,SI_E) | AF9: =IF($Q9=1,0,$AA9*EOSB) | AG9: =$AN9*$W9 | AH9: =SUM($AA9:$AG9) | AI9: =12*($AM9+$AN9) | AJ9: =$AM9*((IncMonth-1)+(13-IncMonth)*(1+$X9))+12*$AN9 | AK9: =IF($R9=1,N($L9)+N($M9),0) | AL9: =IF($C9="","",IF(N($L9)<=0,"Basic salary missing",IF(ISNA(MATCH($C9,Departments!$A$5:$A$54,0)),"Department not on Departments sheet",IF(AND($I9<>"",NOT(ISNUMBER($I9))),"Date of birth is text, not a date",IF(AND($K9<>"",NOT(ISNUMBER($K9))),"Contract end is text, not a date",""))))) | AM9: =IF($R9=0,0,N($L9)*(1+$Z9+BonusMonths/12+IF($Q9=1,0,EOSB))+N($M9)+(N($L9)+SI_Gross*N($M9))*IF($Q9=1,SI_O,SI_E)) | AN9: =IF($R9=0,0,(IF($Q9=1,MedO,MedE+Ticket)+Training)/12)
Q10: =IF($C10="",0,IF(OR(LOWER(TRIM($G10))="omani",LOWER(TRIM($G10))="oman",LOWER(TRIM($G10))="om",LOWER(TRIM($G10))="local"),1,0)) | R10: =IF($C10="",0,IF(OR(ISNUMBER(SEARCH("resign",$N10)),ISNUMBER(SEARCH("terminat",$N10)),ISNUMBER(SEARCH("inactive",$N10)),ISNUMBER(SEARCH("vacan",$N10)),ISNUMBER(SEARCH("deceased",$N10)),ISNUMBER(SEARCH("separated",$N10))),0,1)) | S10: =IF(OR($R10=0,NOT(ISNUMBER($I10))),"",IFERROR(DATEDIF($I10,DATE(FY,1,1),"y"),"")) | T10: =IF(OR($R10=0,NOT(ISNUMBER($J10))),"",IFERROR(DATEDIF($J10,DATE(FY,1,1),"y"),0)) | U10: =IF(OR($R10=0,NOT(ISNUMBER($I10))),0,IF(YEAR($I10)+IF($Q10=1,RetAgeO,RetAgeE)=FY,MONTH($I10),IF(YEAR($I10)+IF($Q10=1,RetAgeO,RetAgeE)<FY,1,0))) | V10: =IF(OR($R10=0,NOT(ISNUMBER($K10))),0,IF(YEAR($K10)=FY,MONTH($K10),IF(YEAR($K10)<FY,1,0))) | W10: =IF($R10=0,0,MIN(12,IF(AND(ISNUMBER($O10),$O10>=1,$O10<=12),INT($O10),12),IF(AND(RetireExit="Yes",$U10>0),$U10,12),IF(AND(ContractExit="Yes",$V10>0),$V10,12))) | X10: =IF(ISNUMBER($P10),$P10,IncPct) | Y10: =IF($W10=0,0,MAX(0,MIN($W10,IncMonth-1))+MAX(0,$W10-IncMonth+1)*(1+$X10)) | Z10: =IF($C10="",0,IFERROR(INDEX(Departments!$B$5:$B$54,MATCH($C10,Departments!$A$5:$A$54,0)),0)) | AA10: =N($L10)*$Y10 | AB10: =N($M10)*$Y10 | AC10: =$AA10*$Z10 | AD10: =$AA10*BonusMonths/12 | AE10: =($AA10+SI_Gross*$AB10)*IF($Q10=1,SI_O,SI_E) | AF10: =IF($Q10=1,0,$AA10*EOSB) | AG10: =$AN10*$W10 | AH10: =SUM($AA10:$AG10) | AI10: =12*($AM10+$AN10) | AJ10: =$AM10*((IncMonth-1)+(13-IncMonth)*(1+$X10))+12*$AN10 | AK10: =IF($R10=1,N($L10)+N($M10),0) | AL10: =IF($C10="","",IF(N($L10)<=0,"Basic salary missing",IF(ISNA(MATCH($C10,Departments!$A$5:$A$54,0)),"Department not on Departments sheet",IF(AND($I10<>"",NOT(ISNUMBER($I10))),"Date of birth is text, not a date",IF(AND($K10<>"",NOT(ISNUMBER($K10))),"Contract end is text, not a date",""))))) | AM10: =IF($R10=0,0,N($L10)*(1+$Z10+BonusMonths/12+IF($Q10=1,0,EOSB))+N($M10)+(N($L10)+SI_Gross*N($M10))*IF($Q10=1,SI_O,SI_E)) | AN10: =IF($R10=0,0,(IF($Q10=1,MedO,MedE+Ticket)+Training)/12)
Q11: =IF($C11="",0,IF(OR(LOWER(TRIM($G11))="omani",LOWER(TRIM($G11))="oman",LOWER(TRIM($G11))="om",LOWER(TRIM($G11))="local"),1,0)) | R11: =IF($C11="",0,IF(OR(ISNUMBER(SEARCH("resign",$N11)),ISNUMBER(SEARCH("terminat",$N11)),ISNUMBER(SEARCH("inactive",$N11)),ISNUMBER(SEARCH("vacan",$N11)),ISNUMBER(SEARCH("deceased",$N11)),ISNUMBER(SEARCH("separated",$N11))),0,1)) | S11: =IF(OR($R11=0,NOT(ISNUMBER($I11))),"",IFERROR(DATEDIF($I11,DATE(FY,1,1),"y"),"")) | T11: =IF(OR($R11=0,NOT(ISNUMBER($J11))),"",IFERROR(DATEDIF($J11,DATE(FY,1,1),"y"),0)) | U11: =IF(OR($R11=0,NOT(ISNUMBER($I11))),0,IF(YEAR($I11)+IF($Q11=1,RetAgeO,RetAgeE)=FY,MONTH($I11),IF(YEAR($I11)+IF($Q11=1,RetAgeO,RetAgeE)<FY,1,0))) | V11: =IF(OR($R11=0,NOT(ISNUMBER($K11))),0,IF(YEAR($K11)=FY,MONTH($K11),IF(YEAR($K11)<FY,1,0))) | W11: =IF($R11=0,0,MIN(12,IF(AND(ISNUMBER($O11),$O11>=1,$O11<=12),INT($O11),12),IF(AND(RetireExit="Yes",$U11>0),$U11,12),IF(AND(ContractExit="Yes",$V11>0),$V11,12))) | X11: =IF(ISNUMBER($P11),$P11,IncPct) | Y11: =IF($W11=0,0,MAX(0,MIN($W11,IncMonth-1))+MAX(0,$W11-IncMonth+1)*(1+$X11)) | Z11: =IF($C11="",0,IFERROR(INDEX(Departments!$B$5:$B$54,MATCH($C11,Departments!$A$5:$A$54,0)),0)) | AA11: =N($L11)*$Y11 | AB11: =N($M11)*$Y11 | AC11: =$AA11*$Z11 | AD11: =$AA11*BonusMonths/12 | AE11: =($AA11+SI_Gross*$AB11)*IF($Q11=1,SI_O,SI_E) | AF11: =IF($Q11=1,0,$AA11*EOSB) | AG11: =$AN11*$W11 | AH11: =SUM($AA11:$AG11) | AI11: =12*($AM11+$AN11) | AJ11: =$AM11*((IncMonth-1)+(13-IncMonth)*(1+$X11))+12*$AN11 | AK11: =IF($R11=1,N($L11)+N($M11),0) | AL11: =IF($C11="","",IF(N($L11)<=0,"Basic salary missing",IF(ISNA(MATCH($C11,Departments!$A$5:$A$54,0)),"Department not on Departments sheet",IF(AND($I11<>"",NOT(ISNUMBER($I11))),"Date of birth is text, not a date",IF(AND($K11<>"",NOT(ISNUMBER($K11))),"Contract end is text, not a date",""))))) | AM11: =IF($R11=0,0,N($L11)*(1+$Z11+BonusMonths/12+IF($Q11=1,0,EOSB))+N($M11)+(N($L11)+SI_Gross*N($M11))*IF($Q11=1,SI_O,SI_E)) | AN11: =IF($R11=0,0,(IF($Q11=1,MedO,MedE+Ticket)+Training)/12)
Q12: =IF($C12="",0,IF(OR(LOWER(TRIM($G12))="omani",LOWER(TRIM($G12))="oman",LOWER(TRIM($G12))="om",LOWER(TRIM($G12))="local"),1,0)) | R12: =IF($C12="",0,IF(OR(ISNUMBER(SEARCH("resign",$N12)),ISNUMBER(SEARCH("terminat",$N12)),ISNUMBER(SEARCH("inactive",$N12)),ISNUMBER(SEARCH("vacan",$N12)),ISNUMBER(SEARCH("deceased",$N12)),ISNUMBER(SEARCH("separated",$N12))),0,1)) | S12: =IF(OR($R12=0,NOT(ISNUMBER($I12))),"",IFERROR(DATEDIF($I12,DATE(FY,1,1),"y"),"")) | T12: =IF(OR($R12=0,NOT(ISNUMBER($J12))),"",IFERROR(DATEDIF($J12,DATE(FY,1,1),"y"),0)) | U12: =IF(OR($R12=0,NOT(ISNUMBER($I12))),0,IF(YEAR($I12)+IF($Q12=1,RetAgeO,RetAgeE)=FY,MONTH($I12),IF(YEAR($I12)+IF($Q12=1,RetAgeO,RetAgeE)<FY,1,0))) | V12: =IF(OR($R12=0,NOT(ISNUMBER($K12))),0,IF(YEAR($K12)=FY,MONTH($K12),IF(YEAR($K12)<FY,1,0))) | W12: =IF($R12=0,0,MIN(12,IF(AND(ISNUMBER($O12),$O12>=1,$O12<=12),INT($O12),12),IF(AND(RetireExit="Yes",$U12>0),$U12,12),IF(AND(ContractExit="Yes",$V12>0),$V12,12))) | X12: =IF(ISNUMBER($P12),$P12,IncPct) | Y12: =IF($W12=0,0,MAX(0,MIN($W12,IncMonth-1))+MAX(0,$W12-IncMonth+1)*(1+$X12)) | Z12: =IF($C12="",0,IFERROR(INDEX(Departments!$B$5:$B$54,MATCH($C12,Departments!$A$5:$A$54,0)),0)) | AA12: =N($L12)*$Y12 | AB12: =N($M12)*$Y12 | AC12: =$AA12*$Z12 | AD12: =$AA12*BonusMonths/12 | AE12: =($AA12+SI_Gross*$AB12)*IF($Q12=1,SI_O,SI_E) | AF12: =IF($Q12=1,0,$AA12*EOSB) | AG12: =$AN12*$W12 | AH12: =SUM($AA12:$AG12) | AI12: =12*($AM12+$AN12) | AJ12: =$AM12*((IncMonth-1)+(13-IncMonth)*(1+$X12))+12*$AN12 | AK12: =IF($R12=1,N($L12)+N($M12),0) | AL12: =IF($C12="","",IF(N($L12)<=0,"Basic salary missing",IF(ISNA(MATCH($C12,Departments!$A$5:$A$54,0)),"Department not on Departments sheet",IF(AND($I12<>"",NOT(ISNUMBER($I12))),"Date of birth is text, not a date",IF(AND($K12<>"",NOT(ISNUMBER($K12))),"Contract end is text, not a date",""))))) | AM12: =IF($R12=0,0,N($L12)*(1+$Z12+BonusMonths/12+IF($Q12=1,0,EOSB))+N($M12)+(N($L12)+SI_Gross*N($M12))*IF($Q12=1,SI_O,SI_E)) | AN12: =IF($R12=0,0,(IF($Q12=1,MedO,MedE+Ticket)+Training)/12)
Q13: =IF($C13="",0,IF(OR(LOWER(TRIM($G13))="omani",LOWER(TRIM($G13))="oman",LOWER(TRIM($G13))="om",LOWER(TRIM($G13))="local"),1,0)) | R13: =IF($C13="",0,IF(OR(ISNUMBER(SEARCH("resign",$N13)),ISNUMBER(SEARCH("terminat",$N13)),ISNUMBER(SEARCH("inactive",$N13)),ISNUMBER(SEARCH("vacan",$N13)),ISNUMBER(SEARCH("deceased",$N13)),ISNUMBER(SEARCH("separated",$N13))),0,1)) | S13: =IF(OR($R13=0,NOT(ISNUMBER($I13))),"",IFERROR(DATEDIF($I13,DATE(FY,1,1),"y"),"")) | T13: =IF(OR($R13=0,NOT(ISNUMBER($J13))),"",IFERROR(DATEDIF($J13,DATE(FY,1,1),"y"),0)) | U13: =IF(OR($R13=0,NOT(ISNUMBER($I13))),0,IF(YEAR($I13)+IF($Q13=1,RetAgeO,RetAgeE)=FY,MONTH($I13),IF(YEAR($I13)+IF($Q13=1,RetAgeO,RetAgeE)<FY,1,0))) | V13: =IF(OR($R13=0,NOT(ISNUMBER($K13))),0,IF(YEAR($K13)=FY,MONTH($K13),IF(YEAR($K13)<FY,1,0))) | W13: =IF($R13=0,0,MIN(12,IF(AND(ISNUMBER($O13),$O13>=1,$O13<=12),INT($O13),12),IF(AND(RetireExit="Yes",$U13>0),$U13,12),IF(AND(ContractExit="Yes",$V13>0),$V13,12))) | X13: =IF(ISNUMBER($P13),$P13,IncPct) | Y13: =IF($W13=0,0,MAX(0,MIN($W13,IncMonth-1))+MAX(0,$W13-IncMonth+1)*(1+$X13)) | Z13: =IF($C13="",0,IFERROR(INDEX(Departments!$B$5:$B$54,MATCH($C13,Departments!$A$5:$A$54,0)),0)) | AA13: =N($L13)*$Y13 | AB13: =N($M13)*$Y13 | AC13: =$AA13*$Z13 | AD13: =$AA13*BonusMonths/12 | AE13: =($AA13+SI_Gross*$AB13)*IF($Q13=1,SI_O,SI_E) | AF13: =IF($Q13=1,0,$AA13*EOSB) | AG13: =$AN13*$W13 | AH13: =SUM($AA13:$AG13) | AI13: =12*($AM13+$AN13) | AJ13: =$AM13*((IncMonth-1)+(13-IncMonth)*(1+$X13))+12*$AN13 | AK13: =IF($R13=1,N($L13)+N($M13),0) | AL13: =IF($C13="","",IF(N($L13)<=0,"Basic salary missing",IF(ISNA(MATCH($C13,Departments!$A$5:$A$54,0)),"Department not on Departments sheet",IF(AND($I13<>"",NOT(ISNUMBER($I13))),"Date of birth is text, not a date",IF(AND($K13<>"",NOT(ISNUMBER($K13))),"Contract end is text, not a date",""))))) | AM13: =IF($R13=0,0,N($L13)*(1+$Z13+BonusMonths/12+IF($Q13=1,0,EOSB))+N($M13)+(N($L13)+SI_Gross*N($M13))*IF($Q13=1,SI_O,SI_E)) | AN13: =IF($R13=0,0,(IF($Q13=1,MedO,MedE+Ticket)+Training)/12)
... Q5001: =IF($C5001="",0,IF(OR(LOWER(TRIM($G5001))="omani",LOWER(TRIM($G5001))="oman",LOWER(TRIM($G5001))="om",LOWER(TRIM($G5001))="local"),1,0)) | R5001: =IF($C5001="",0,IF(OR(ISNUMBER(SEARCH("resign",$N5001)),ISNUMBER(SEARCH("terminat",$N5001)),ISNUMBER(SEARCH("inactive",$N5001)),ISNUMBER(SEARCH("vacan",$N5001)),ISNUMBER(SEARCH("deceased",$N5001)),ISNUMBER(SEARCH("separated",$N5001))),0,1)) | S5001: =IF(OR($R5001=0,NOT(ISNUMBER($I5001))),"",IFERROR(DATEDIF($I5001,DATE(FY,1,1),"y"),"")) | T5001: =IF(OR($R5001=0,NOT(ISNUMBER($J5001))),"",IFERROR(DATEDIF($J5001,DATE(FY,1,1),"y"),0)) | U5001: =IF(OR($R5001=0,NOT(ISNUMBER($I5001))),0,IF(YEAR($I5001)+IF($Q5001=1,RetAgeO,RetAgeE)=FY,MONTH($I5001),IF(YEAR($I5001)+IF($Q5001=1,RetAgeO,RetAgeE)<FY,1,0))) | V5001: =IF(OR($R5001=0,NOT(ISNUMBER($K5001))),0,IF(YEAR($K5001)=FY,MONTH($K5001),IF(YEAR($K5001)<FY,1,0))) | W5001: =IF($R5001=0,0,MIN(12,IF(AND(ISNUMBER($O5001),$O5001>=1,$O5001<=12),INT($O5001),12),IF(AND(RetireExit="Yes",$U5001>0),$U5001,12),IF(AND(ContractExit="Yes",$V5001>0),$V5001,12))) | X5001: =IF(ISNUMBER($P5001),$P5001,IncPct) | Y5001: =IF($W5001=0,0,MAX(0,MIN($W5001,IncMonth-1))+MAX(0,$W5001-IncMonth+1)*(1+$X5001)) | Z5001: =IF($C5001="",0,IFERROR(INDEX(Departments!$B$5:$B$54,MATCH($C5001,Departments!$A$5:$A$54,0)),0)) | AA5001: =N($L5001)*$Y5001 | AB5001: =N($M5001)*$Y5001 | AC5001: =$AA5001*$Z5001 | AD5001: =$AA5001*BonusMonths/12 | AE5001: =($AA5001+SI_Gross*$AB5001)*IF($Q5001=1,SI_O,SI_E) | AF5001: =IF($Q5001=1,0,$AA5001*EOSB) | AG5001: =$AN5001*$W5001 | AH5001: =SUM($AA5001:$AG5001) | AI5001: =12*($AM5001+$AN5001) | AJ5001: =$AM5001*((IncMonth-1)+(13-IncMonth)*(1+$X5001))+12*$AN5001 | AK5001: =IF($R5001=1,N($L5001)+N($M5001),0) | AL5001: =IF($C5001="","",IF(N($L5001)<=0,"Basic salary missing",IF(ISNA(MATCH($C5001,Departments!$A$5:$A$54,0)),"Department not on Departments sheet",IF(AND($I5001<>"",NOT(ISNUMBER($I5001))),"Date of birth is text, not a date",IF(AND($K5001<>"",NOT(ISNUMBER($K5001))),"Contract end is text, not a date",""))))) | AM5001: =IF($R5001=0,0,N($L5001)*(1+$Z5001+BonusMonths/12+IF($Q5001=1,0,EOSB))+N($M5001)+(N($L5001)+SI_Gross*N($M5001))*IF($Q5001=1,SI_O,SI_E)) | AN5001: =IF($R5001=0,0,(IF($Q5001=1,MedO,MedE+Ticket)+Training)/12)

Sheet Plan
A1: Plan: new hires and other exits
A2: Positions not yet in the Data sheet (hires) and leavers who are not named there (attrition). Month = start month for a hire, last month on payroll for an exit.
A3: Plan checks: | B3: =IF(SUMPRODUCT((Plan!$A$5:$A$304<>"")*((Plan!$B$5:$B$304="")+(Plan!$D$5:$D$304="")+(N(+Plan!$E$5:$E$304)=0)))>0,"Some plan lines are missing department, nationality or number","All plan lines complete")
A4: Type (Hire / Exit) | B4: Department | C4: Position | D4: Nationality | E4: Number | F4: Month (1-12) | G4: Basic (OMR / month) | H4: Allowances (OMR / month) | I4: Reason / request reference | J4: Omani (1/0) | K4: Sign | L4: First month affected | M4: Last month affected | N4: Paid months per head incl. increment | O4: Department overtime % | P4: Months affected | Q4: Cost per head (OMR) | R4: Recruitment (OMR) | S4: Total effect (OMR) | T4: Heads effect | U4: Monthly cost rate per head (OMR) | V4: Monthly per-head costs (OMR)
J5: =IF($D5="Omani",1,0) | K5: =IF($A5="Hire",1,IF($A5="Exit",-1,0)) | L5: =IF($K5=1,MAX(1,N($F5)),IF($K5=-1,N($F5)+1,13)) | M5: =12 | N5: =MAX(0,MIN($M5,IncMonth-1)-$L5+1)+MAX(0,$M5-MAX($L5,IncMonth)+1)*(1+IncPct) | O5: =IF($B5="",0,IFERROR(INDEX(Departments!$B$5:$B$54,MATCH($B5,Departments!$A$5:$A$54,0)),0)) | P5: =MAX(0,$M5-$L5+1) | Q5: =$U5*$N5+$V5*$P5 | R5: =IF($K5=1,N($E5)*IF($J5=1,RecO,RecE),0) | S5: =$K5*N($E5)*$Q5+$R5 | T5: =$K5*N($E5) | U5: =N($G5)*(1+$O5+BonusMonths/12+IF($J5=1,0,EOSB))+N($H5)+(N($G5)+SI_Gross*N($H5))*IF($J5=1,SI_O,SI_E) | V5: =(IF($J5=1,MedO,MedE+Ticket)+Training)/12
